Workbook

Sheet Описание
A1: Кейс ВТБ «Деньги под защитой» | Cup Moscow 2026 | Команда «Омский пряник»
A2: Иллюстрация механизма, не прогноз. Допущения команды (гипотезы помечены); данные рынка: Банк России, обзор ОБДС, I-II кв. 2026.
A4: Назначение | B4: Модель экономики и KPI решения «Адаптивное трение» (В3). Фокус: переводы физлиц в ДБО (СБП и счета), сценарии «безопасный счет» и захват доступа.
A5: Статус | B5: Иллюстрация механизма, не прогноз. Внутренних данных ВТБ нет: гипотезы помечены на листе «Допущения».
A6: Как пользоваться | B6: Меняйте только желтые ячейки на листе «Допущения». Все остальные листы пересчитываются формулами.
A7: Цвета | B7: Синий шрифт на желтом: вход. Черный: формула. Зеленый: ссылка на другой лист. Зеленая заливка: ключевой результат.
A8: Словарь | B8: ОБДС: операция без добровольного согласия клиента. Сигнал: срабатывание антифрода. Ограничение: реально остановленная операция (пауза, отказ, блок). Сохраненные средства клиентов: KPI, не доход банка.
A9: Метрики | B9: Точность = TP/(TP+FP); доля ложных сигналов = FP/(TP+FP); доля ложных срабатываний среди законных = FP/(FP+TN); полнота = TP/(TP+FN).
A10: Убыток от ошибки | B10: Сумма отклоненного законного перевода не убыток банка. Убыток = обращение в поддержку + разбор + недополученный доход + отток клиентов.
A11: Регуляторный слой | B11: 12 признаков ОБДС по приказу Банка России от 05.11.2025 № ОД-2506 (с 01.01.2026; ст. 8 161-ФЗ) работают отдельно и не переопределяются моделью.
A13: Лист | B13: Содержание
A14: Допущения | B14: Все входные параметры с источником, статусом и диапазоном
A15: База | B15: Базовые потери (квартал → год), доля ВТБ, число операций, средний чек
A16: KPI | B16: Пять показателей «было → стало» для трех сценариев (слайд 6)
... A23: Варианты | B23: Взвешенная оценка В1-В4, стоимость и срок, метрики симуляции на синтетических данных

Sheet Допущения
A1: Допущения: все входы модели
A2: Иллюстрация механизма, не прогноз. Допущения команды (гипотезы помечены); данные рынка: Банк России, обзор ОБДС, I-II кв. 2026.
A3: Желтые ячейки с синим шрифтом: входы (менять только здесь). Черный шрифт: формулы. Зеленый: ссылки на другие листы. Сценарии: П = пессимист, Б = база, О = оптимист.
A5: № | B5: Параметр | C5: Пессимист | D5: База | E5: Оптимист | F5: Ед. | G5: Диапазон | H5: Статус | I5: Источник / комментарий
A6: Рамки кейса
A7: A1 | B7: Число клиентов-физлиц ВТБ | D7: 30.3 | F7: млн | H7: кейс | I7: Материалы кейса, стр. 6; решение команды (24,5 млн не используем). Справочно: МСФО ВТБ за I п/г 2026: 31,3 млн активных розничных клиентов
A8: A2 | B8: Пользователи «ВТБ Онлайн» | D8: 22 | F8: млн | G8: > 22 | H8: кейс | I8: Материалы кейса. Справочно: СМИ на конец 2025 г. ≈ 27 млн MAU; 22 млн консервативно
A9: R1 | B9: Лимит бюджета внедрения | D9: 50 | F9: млн руб. | H9: кейс | I9: Ограничение кейса
A10: R2 | B10: Лимит срока внедрения | D10: 6 | F10: мес. | H10: кейс | I10: Ограничение кейса
A11: Данные рынка: Банк России, обзор операций без добровольного согласия клиентов (ОБДС)
A12: M1 | B12: ОБДС, все клиенты, I кв. 2026: сумма | D12: 7397.91 | F12: млн руб. | H12: факт | I12: Банк России, обзор ОБДС за I кв. 2026: https://cbr.ru/statistics/ib/review_1q_2026/
A13: M2 | B13: ОБДС, все клиенты, I кв. 2026: операций | D13: 495761 | F13: шт. | H13: факт | I13: Банк России, обзор ОБДС за I кв. 2026: https://cbr.ru/statistics/ib/review_1q_2026/
A14: M3 | B14: ОБДС, все клиенты, II кв. 2026: сумма | D14: 7350.72 | F14: млн руб. | H14: факт | I14: Банк России, обзор ОБДС за II кв. 2026 (опубл. 04.08.2026): https://cbr.ru/statistics/ib/review_2q_2026/
A15: M4 | B15: ОБДС, все клиенты, II кв. 2026: операций | D15: 458655 | F15: шт. | H15: факт | I15: Банк России, обзор ОБДС за II кв. 2026 (опубл. 04.08.2026): https://cbr.ru/statistics/ib/review_2q_2026/
A16: M5 | B16: Физлица, переводы со счета (ДБО), II кв. 2026: сумма | D16: 2.17 | F16: млрд руб. | H16: факт | I16: Банк России, обзор ОБДС за II кв. 2026 (опубл. 04.08.2026): https://cbr.ru/statistics/ib/review_2q_2026/
A17: M6 | B17: Физлица, переводы со счета (ДБО), II кв. 2026: операций | D17: 84.02 | F17: тыс. | H17: факт | I17: Банк России, обзор ОБДС за II кв. 2026 (опубл. 04.08.2026): https://cbr.ru/statistics/ib/review_2q_2026/
A18: M7 | B18: Физлица, СБП, II кв. 2026: сумма | D18: 2.74 | F18: млрд руб. | H18: факт | I18: Банк России, обзор ОБДС за II кв. 2026 (опубл. 04.08.2026): https://cbr.ru/statistics/ib/review_2q_2026/
A19: M8 | B19: Физлица, СБП, II кв. 2026: операций | D19: 129.06 | F19: тыс. | H19: факт | I19: Банк России, обзор ОБДС за II кв. 2026 (опубл. 04.08.2026): https://cbr.ru/statistics/ib/review_2q_2026/
A20: M9 | B20: Физлица, карты, II кв. 2026: сумма (вне фокуса) | D20: 1.3 | F20: млрд руб. | H20: факт | I20: Банк России, обзор ОБДС за II кв. 2026 (опубл. 04.08.2026): https://cbr.ru/statistics/ib/review_2q_2026/
A21: M10 | B21: Физлица, карты, II кв. 2026: операций (вне фокуса) | D21: 237.03 | F21: тыс. | H21: факт | I21: Банк России, обзор ОБДС за II кв. 2026 (опубл. 04.08.2026): https://cbr.ru/statistics/ib/review_2q_2026/
A22: M11 | B22: Физлица, электронные кошельки, II кв. 2026: сумма (вне фокуса) | D22: 0.06 | F22: млрд руб. | H22: факт | I22: Банк России, обзор ОБДС за II кв. 2026 (опубл. 04.08.2026): https://cbr.ru/statistics/ib/review_2q_2026/
A23: M12 | B23: Физлица, электронные кошельки, II кв. 2026: операций | D23: 6 | F23: тыс. | H23: факт | I23: Банк России, обзор ОБДС за II кв. 2026 (опубл. 04.08.2026): https://cbr.ru/statistics/ib/review_2q_2026/
... A29: M18 | B29: Возвращено клиентам, СБП, II кв. 2026 | D29: 0.021 | F29: % объема | H29: факт | I29: Банк России, II кв. 2026; сверка для A21
A30: A3 | B30: Годовая база ОБДС по рынку | D30: =($D$12+$D$14)*2/1000 | F30: млрд руб./год | H30: расчет | I30: (I кв. + II кв.) × 2
A31: A4 | B31: Годовые потери физлиц рынка в фокусе (СБП + счета) | D31: =($D$16+$D$18)*4 | F31: млрд руб./год | H31: расчет | I31: II кв. × 4 (поканальной разбивки за I кв. нет)
A32: 4.1 База потерь ВТБ
A33: A5 | B33: Доля ВТБ в потерях фокуса | D33: 0.1 | F33: % | G33: 7-13% | H33: гипотеза | I33: Открытых данных о доле ВТБ в переводах физлиц/СБП не нашли (поиск 27.10); явное допущение с диапазоном
A34: A6 | B34: Потери клиентов ВТБ в фокусе (было) | D34: =$D$31*$D$33*1000 | F34: млн руб./год | H34: расчет | I34: A4 × A5
A35: 4.2 Выявление мошенничества
A36: A7 | B36: Полнота выявления сейчас (по сумме) | D36: 0.8 | F36: % | H36: гипотеза | I36: Внутренних данных ВТБ нет. Не путать с «предотвращенные / совершенные»: там есть ложные срабатывания
A37: A8 | B37: Полнота выявления после (по сумме) | C37: 0.82 | D37: 0.84 | E37: 0.86 | F37: % | H37: гипотеза | I37: Сценарии П / Б / О
A38: A9 | B38: Сокращение потерь = (R_после − R_сейчас) / (1 − R_сейчас) | C38: =($C$37-$D$36)/(1-$D$36) | D38: =($D$37-$D$36)/(1-$D$36) | E38: =($E$37-$D$36)/(1-$D$36) | F38: % | H38: расчет | I38: По A7-A8
A39: A9a | B39: Снижение числа попыток (эффект сдерживания) | C39: 0 | D39: 0 | E39: 0.03 | F39: % | G39: 0-3% | H39: гипотеза | I39: В пессимисте и базе не учитываем; риск адаптации мошенников
A40: 4.3 Ложные срабатывания и клиентский опыт
A41: A10a | B41: Доля активных пользователей «ВТБ Онлайн» | D41: 0.7 | F41: % | H41: гипотеза | I41: Проверить по статистике платежей
A42: A10b | B42: Переводов физлицам в месяц на активного пользователя | D42: 5 | F42: шт./мес. | H42: гипотеза | I42: Проверить по статистике платежей
A43: A10 | B43: Законные переводы физлиц в фокусе у ВТБ | D43: =$D$8*$D$41*$D$42*12 | F43: млн/год | H43: расчет | I43: A2 × A10a × A10b × 12
A44: A11a | B44: Доля законных переводов с сигналом: сейчас | D44: 0.015 | F44: % | H44: гипотеза
A45: A11b | B45: Доля законных переводов с сигналом: после | D45: 0.018 | F45: % | H45: гипотеза | I45: Сигналов чуть больше: больше точечных предупреждений
A46: A12a | B46: Доля сигналов, ставших ошибочным ограничением: сейчас | D46: 0.35 | F46: % | H46: гипотеза | I46: Ограничение = пауза, отказ, блок. Сигнал ≠ ограничение
...

Sheet База
A1: База: потери рынка и ВТБ (квартал → год)
A2: Иллюстрация механизма, не прогноз. Допущения команды (гипотезы помечены); данные рынка: Банк России, обзор ОБДС, I-II кв. 2026.
B4: Показатель | C4: Значение | D4: Ед. | E4: Как считается
A5: Рынок, все клиенты
B6: ОБДС, I кв. 2026: сумма | C6: ='Допущения'!$D$12 | D6: млн руб. | E6: Банк России
B7: ОБДС, II кв. 2026: сумма | C7: ='Допущения'!$D$14 | D7: млн руб. | E7: Банк России
B8: ОБДС, I кв. 2026: операций | C8: ='Допущения'!$D$13 | D8: шт. | E8: Банк России
B9: ОБДС, II кв. 2026: операций | C9: ='Допущения'!$D$15 | D9: шт. | E9: Банк России
B10: Годовая база ОБДС по рынку | C10: ='Допущения'!$D$30 | D10: млрд руб./год | E10: (I кв. + II кв.) × 2
A11: Физлица по каналам, II кв. 2026
B12: Переводы со счета (ДБО): сумма | C12: ='Допущения'!$D$16 | D12: млрд руб.
B13: Переводы со счета (ДБО): операций | C13: ='Допущения'!$D$17 | D13: тыс.
B14: Переводы со счета (ДБО): средний чек | C14: =IF($C$13=0,0,$C$12/$C$13*1000) | D14: тыс. руб. | E14: сумма / операции
B15: СБП: сумма | C15: ='Допущения'!$D$18 | D15: млрд руб.
B16: СБП: операций | C16: ='Допущения'!$D$19 | D16: тыс.
B17: СБП: средний чек | C17: =IF($C$16=0,0,$C$15/$C$16*1000) | D17: тыс. руб. | E17: сумма / операции
B18: Карты (вне фокуса): сумма | C18: ='Допущения'!$D$20 | D18: млрд руб.
B19: Карты (вне фокуса): операций | C19: ='Допущения'!$D$21 | D19: тыс.
B20: Карты (вне фокуса): средний чек | C20: =IF($C$19=0,0,$C$18/$C$19*1000) | D20: тыс. руб. | E20: сумма / операции
B21: Итого физлица: сумма | C21: ='Допущения'!$D$16+'Допущения'!$D$18+'Допущения'!$D$20+'Допущения'!$D$22+'Допущения'!$D$24 | D21: млрд руб. | E21: все каналы физлиц
B22: Итого физлица: операций | C22: ='Допущения'!$D$17+'Допущения'!$D$19+'Допущения'!$D$21+'Допущения'!$D$23+'Допущения'!$D$25 | D22: тыс. | E22: все каналы физлиц
B23: Фокус (СБП + счета): сумма за квартал | C23: =$C$12+$C$15 | D23: млрд руб.
B24: Фокус (СБП + счета): операций за квартал | C24: =$C$13+$C$16 | D24: тыс.
B25: Доля фокуса в сумме ОБДС физлиц | C25: =IF($C$21=0,0,$C$23/$C$21) | D25: % | E25: аргумент для слайда 2
B26: Доля фокуса в операциях ОБДС физлиц | C26: =IF($C$22=0,0,$C$24/$C$22) | D26: % | E26: аргумент для слайда 2
A27: ВТБ, годовая основа
B28: Годовые потери физлиц рынка в фокусе | C28: ='Допущения'!$D$31 | D28: млрд руб./год | E28: квартал × 4
B29: Доля ВТБ в потерях фокуса | C29: ='Допущения'!$D$33 | D29: % | E29: гипотеза
B30: Потери клиентов ВТБ в фокусе (было) | C30: ='Допущения'!$D$34 | D30: млн руб./год | E30: A4 × A5
B31: Операций ОБДС в фокусе у ВТБ | C31: =$C$24*4*'Допущения'!$D$33 | D31: тыс./год | E31: операции фокуса × 4 × A5
B32: Средний чек ОБДС в фокусе | C32: =IF($C$24=0,0,$C$23/$C$24*1000) | D32: тыс. руб.
B33: Попытки хищения в фокусе у ВТБ (по сумме) | C33: =IF(1-'Допущения'!$D$36=0,0,$C$30/(1-'Допущения'!$D$36)) | D33: млн руб./год | E33: потери = попытки × (1 − полнота A7)
B34: Попытки хищения в фокусе у ВТБ (по числу) | C34: =IF(1-'Допущения'!$D$36=0,0,$C$31/(1-'Допущения'!$D$36)) | D34: тыс./год | E34: ОБДС = попытки × (1 − полнота A7); полнота по числу = по сумме (допущение)
A35: Сверка допущений с фактами Банка России
B36: Потери физлиц в фокусе, факт 2025 года | C36: =('Допущения'!$D$26+'Допущения'!$D$27)/1000 | D36: млрд руб. | E36: M15 + M16
B37: Отклонение A4 (II кв. × 4) от факта 2025 | C37: =IF($C$36=0,0,'Допущения'!$D$31/$C$36-1) | D37: % | E37: < 0: оценка A4 консервативна
B38: Доля возврата клиентам в фокусе, II кв. 2026 (взвешенно по сумме) | C38: =IF($C$23=0,0,('Допущения'!$D$16*'Допущения'!$D$28+'Допущения'!$D$18*'Допущения'!$D$29)/$C$23) | D38: % | E38: сравнить с A21
B39: A21: доля сохраненных средств → избежанный расход банка | C39: ='Допущения'!$D$65 | D39: % | E39: гипотеза команды

Sheet KPI
A1: KPI «было → стало» (слайд 6)
A2: Иллюстрация механизма, не прогноз. Допущения команды (гипотезы помечены); данные рынка: Банк России, обзор ОБДС, I-II кв. 2026.
B4: Показатель | C4: Ед. | D4: Было | E4: Стало: пессимист | F4: Стало: база | G4: Стало: оптимист | H4: Комментарий
B5: 1. Потери клиентов ВТБ в фокусе | C5: млн руб./год | D5: ='Допущения'!$D$34 | E5: ='Допущения'!$D$34*(1-'Допущения'!$C$39)*(1-'Допущения'!$C$37)/(1-'Допущения'!$D$36) | F5: ='Допущения'!$D$34*(1-'Допущения'!$D$39)*(1-'Допущения'!$D$37)/(1-'Допущения'!$D$36) | G5: ='Допущения'!$D$34*(1-'Допущения'!$E$39)*(1-'Допущения'!$E$37)/(1-'Допущения'!$D$36) | H5: потери = попытки × (1 − полнота)
B6: Сохраненные средства клиентов (KPI, не доход банка) | C6: млн руб./год | E6: =$D$5-E5 | F6: =$D$5-F5 | G6: =$D$5-G5 | H6: не доход банка
B7: Сокращение потерь | C7: % | E7: =IF($D$5=0,0,E6/$D$5) | F7: =IF($D$5=0,0,F6/$D$5) | G7: =IF($D$5=0,0,G6/$D$5)
B8: 2. Полнота выявления (по сумме) | C8: % | D8: ='Допущения'!$D$36 | E8: ='Допущения'!$C$37 | F8: ='Допущения'!$D$37 | G8: ='Допущения'!$E$37 | H8: гипотеза
B9: Корректно выявлено мошеннических операций | C9: тыс./год | D9: ='База'!$C$34*'Допущения'!$D$36 | E9: ='База'!$C$34*(1-'Допущения'!$C$39)*'Допущения'!$C$37 | F9: ='База'!$C$34*(1-'Допущения'!$D$39)*'Допущения'!$D$37 | G9: ='База'!$C$34*(1-'Допущения'!$E$39)*'Допущения'!$E$37 | H9: TP = попытки (шт.) × полнота; формулировка кейса
B10: Изменение числа выявленных | C10: % | E10: =IF($D$9=0,0,E9/$D$9-1) | F10: =IF($D$9=0,0,F9/$D$9-1) | G10: =IF($D$9=0,0,G9/$D$9-1) | H10: в оптимисте попыток меньше (сдерживание)
B11: 3. Ошибочные ограничения (доля законных переводов) | C11: % | D11: ='Ложные срабатывания'!$D$13 | E11: ='Ложные срабатывания'!$E$13 | F11: ='Ложные срабатывания'!$F$13 | G11: ='Ложные срабатывания'!$G$13
B12: Изменение ошибочных ограничений | C12: % | E12: =IF($D$11=0,0,E11/$D$11-1) | F12: =IF($D$11=0,0,F11/$D$11-1) | G12: =IF($D$11=0,0,G11/$D$11-1)
B13: 4. NPS банка в целом: изменение | C13: п. | D13: 0 | E13: ='NPS'!$E$10 | F13: ='NPS'!$F$10 | G13: ='NPS'!$G$10 | H13: было = базовое значение NPS
B14: 5. Число попыток мошенничества: изменение | C14: % | D14: 0 | E14: =-'Допущения'!$C$39 | F14: =-'Допущения'!$D$39 | G14: =-'Допущения'!$E$39 | H14: опционально; риск адаптации мошенников
B15: Справочно: клиенты с ошибочным ограничением | C15: млн | D15: ='Ложные срабатывания'!$D$16 | E15: ='Ложные срабатывания'!$E$16 | F15: ='Ложные срабатывания'!$F$16 | G15: ='Ложные срабатывания'!$G$16

Sheet Ложные срабатывания
A1: Ложные срабатывания: сигналы ≠ ограничения
A2: Иллюстрация механизма, не прогноз. Допущения команды (гипотезы помечены); данные рынка: Банк России, обзор ОБДС, I-II кв. 2026.
B4: Показатель | C4: Ед. | D4: Сейчас | E4: После: пессимист | F4: После: база | G4: После: оптимист | H4: Комментарий
B5: Законные переводы физлиц в фокусе | C5: млн/год | D5: ='Допущения'!$D$43 | E5: ='Допущения'!$D$43 | F5: ='Допущения'!$D$43 | G5: ='Допущения'!$D$43 | H5: A10
B6: Доля законных переводов с сигналом | C6: % | D6: ='Допущения'!$D$44 | E6: ='Допущения'!$D$45 | F6: ='Допущения'!$D$45 | G6: ='Допущения'!$D$45 | H6: A11
B7: Сигналы на законных переводах (FP) | C7: млн/год | D7: =D5*D6 | E7: =E5*E6 | F7: =F5*F6 | G7: =G5*G6
B8: Законные переводы без сигнала (TN) | C8: млн/год | D8: =D5-D7 | E8: =E5-E7 | F8: =F5-F7 | G8: =G5-G7
B9: Доля ложных срабатываний среди законных = FP / (FP + TN) | C9: % | D9: =IF(D7+D8=0,0,D7/(D7+D8)) | E9: =IF(E7+E8=0,0,E7/(E7+E8)) | F9: =IF(F7+F8=0,0,F7/(F7+F8)) | G9: =IF(G7+G8=0,0,G7/(G7+G8))
B10: Доля сигналов, ставших ошибочным ограничением | C10: % | D10: ='Допущения'!$D$46 | E10: ='Допущения'!$C$47 | F10: ='Допущения'!$D$47 | G10: ='Допущения'!$E$47 | H10: A12
B11: Доля сигналов, снятых предупреждением или быстрым подтверждением | C11: % | D11: =1-D10 | E11: =1-E10 | F11: =1-F10 | G11: =1-G10 | H11: не превращаются в ограничения
B12: Ошибочные ограничения (пауза, отказ, блок) | C12: млн/год | D12: =D7*D10 | E12: =E7*E10 | F12: =F7*F10 | G12: =G7*G10
B13: Ошибочные ограничения, доля законных переводов | C13: % | D13: =IF(D5=0,0,D12/D5) | E13: =IF(E5=0,0,E12/E5) | F13: =IF(F5=0,0,F12/F5) | G13: =IF(G5=0,0,G12/G5) | H13: сверка с A13
B14: Прямая стоимость одного ошибочного ограничения | C14: руб. | D14: ='Допущения'!$D$59 | E14: ='Допущения'!$D$59 | F14: ='Допущения'!$D$59 | G14: ='Допущения'!$D$59 | H14: поддержка + разбор + комиссии
B15: Прямая стоимость ошибочных ограничений | C15: млн руб./год | D15: =D12*D14 | E15: =E12*E14 | F15: =F12*F14 | G15: =G12*G14
B16: Затронуто клиентов | C16: млн | D16: =D12/'Допущения'!$D$60 | E16: =E12/'Допущения'!$D$60 | F16: =F12/'Допущения'!$D$60 | G16: =G12/'Допущения'!$D$60 | H16: A17 ограничений на клиента
B17: Недополученный доход из-за оттока | C17: млн руб./год | D17: =D16*'Допущения'!$D$61*'Допущения'!$D$62 | E17: =E16*'Допущения'!$D$61*'Допущения'!$D$62 | F17: =F16*'Допущения'!$D$61*'Допущения'!$D$62 | G17: =G16*'Допущения'!$D$61*'Допущения'!$D$62 | H17: клиенты × A18 × A19
B18: Полная стоимость ошибочных ограничений | C18: млн руб./год | D18: =D15+D17 | E18: =E15+E17 | F18: =F15+F17 | G18: =G15+G17
A19: Эффект к состоянию «сейчас»
B20: Снижение ошибочных ограничений | C20: млн/год | E20: =$D$12-E12 | F20: =$D$12-F12 | G20: =$D$12-G12
B21: Снижение ошибочных ограничений, % | C21: % | E21: =IF($D$12=0,0,E20/$D$12) | F21: =IF($D$12=0,0,F20/$D$12) | G21: =IF($D$12=0,0,G20/$D$12)
B22: Экономия на ошибочных ограничениях (прямая) | C22: млн руб./год | E22: =$D$15-E15 | F22: =$D$15-F15 | G22: =$D$15-G15
B23: Удержание клиентов (меньше оттока) | C23: млн руб./год | E23: =$D$17-E17 | F23: =$D$17-F17 | G23: =$D$17-G17
B24: Меньше затронутых клиентов | C24: млн | E24: =$D$16-E16 | F24: =$D$16-F16 | G24: =$D$16-G16

Sheet NPS
A1: NPS: эффект от снижения ошибочных ограничений
A2: Иллюстрация механизма, не прогноз. Допущения команды (гипотезы помечены); данные рынка: Банк России, обзор ОБДС, I-II кв. 2026.
B4: Показатель | C4: Ед. | D4: Сейчас | E4: После: пессимист | F4: После: база | G4: После: оптимист | H4: Комментарий
B5: Клиентов-физлиц ВТБ | C5: млн | D5: ='Допущения'!$D$7 | E5: ='Допущения'!$D$7 | F5: ='Допущения'!$D$7 | G5: ='Допущения'!$D$7 | H5: A1, решение команды
B6: Затронуто ошибочными ограничениями | C6: млн | D6: ='Ложные срабатывания'!$D$16 | E6: ='Ложные срабатывания'!$E$16 | F6: ='Ложные срабатывания'!$F$16 | G6: ='Ложные срабатывания'!$G$16
B7: Доля затронутых клиентов | C7: % | D7: =IF(D5=0,0,D6/D5) | E7: =IF(E5=0,0,E6/E5) | F7: =IF(F5=0,0,F6/F5) | G7: =IF(G5=0,0,G6/G5)
B8: Разница NPS: затронутые против остальных | C8: п. | D8: ='Допущения'!$D$63 | E8: ='Допущения'!$D$63 | F8: ='Допущения'!$D$63 | G8: ='Допущения'!$D$63 | H8: A20
B9: Вклад ошибочных ограничений в NPS банка | C9: п. | D9: =D7*D8 | E9: =E7*E8 | F9: =F7*F8 | G9: =G7*G8 | H9: доля × разница
B10: Изменение NPS банка к «сейчас» | C10: п. | E10: =E9-$D$9 | F10: =F9-$D$9 | G10: =G9-$D$9 | H10: на слайд 6

Sheet Затраты
A1: Затраты: смета внедрения по месяцам (≤ 50 млн руб., ≤ 6 мес.) и эксплуатация
A2: Иллюстрация механизма, не прогноз. Допущения команды (гипотезы помечены); данные рынка: Банк России, обзор ОБДС, I-II кв. 2026.
B4: Статья | C4: Итого, млн руб. | D4: М1 | E4: М2 | F4: М3 | G4: М4 | H4: М5 | I4: М6 | J4: Как считается
B5: Команда проекта | C5: ='Допущения'!$D$69*'Допущения'!$D$70*'Допущения'!$D$66 | D5: =$C5*'Допущения'!$C$92 | E5: =$C5*'Допущения'!$D$92 | F5: =$C5*'Допущения'!$E$92 | G5: =$C5*'Допущения'!$F$92 | H5: =$C5*'Допущения'!$G$92 | I5: =$C5*'Допущения'!$H$92 | J5: C1 FTE × C2 мес. × A22
B6: Инфраструктура, данные, ПО | C6: ='Допущения'!$D$71 | D6: =$C6*'Допущения'!$C$93 | E6: =$C6*'Допущения'!$D$93 | F6: =$C6*'Допущения'!$E$93 | G6: =$C6*'Допущения'!$F$93 | H6: =$C6*'Допущения'!$G$93 | I6: =$C6*'Допущения'!$H$93 | J6: C3
B7: Контакт-центр: обучение, скрипты, коммуникации | C7: ='Допущения'!$D$72 | D7: =$C7*'Допущения'!$C$94 | E7: =$C7*'Допущения'!$D$94 | F7: =$C7*'Допущения'!$E$94 | G7: =$C7*'Допущения'!$F$94 | H7: =$C7*'Допущения'!$G$94 | I7: =$C7*'Допущения'!$H$94 | J7: C4
B8: Внешний аудит, комплаенс, ИБ | C8: ='Допущения'!$D$73 | D8: =$C8*'Допущения'!$C$95 | E8: =$C8*'Допущения'!$D$95 | F8: =$C8*'Допущения'!$E$95 | G8: =$C8*'Допущения'!$F$95 | H8: =$C8*'Допущения'!$G$95 | I8: =$C8*'Допущения'!$H$95 | J8: C5
B9: Итого статей | C9: =SUM(C5:C8) | D9: =SUM(D5:D8) | E9: =SUM(E5:E8) | F9: =SUM(F5:F8) | G9: =SUM(G5:G8) | H9: =SUM(H5:H8) | I9: =SUM(I5:I8)
B10: Резерв | C10: =C9*'Допущения'!$D$74 | D10: =D9*'Допущения'!$D$74 | E10: =E9*'Допущения'!$D$74 | F10: =F9*'Допущения'!$D$74 | G10: =G9*'Допущения'!$D$74 | H10: =H9*'Допущения'!$D$74 | I10: =I9*'Допущения'!$D$74 | J10: C6 × итого статей
B11: Итого внедрение | C11: =C9+C10 | D11: =D9+D10 | E11: =E9+E10 | F11: =F9+F10 | G11: =G9+G10 | H11: =H9+H10 | I11: =I9+I10
B12: Проверка: сумма по месяцам = итого | C12: =IF(ABS(SUM(D11:I11)-C11)<0.0001,"OK","Ошибка: проверьте доли")
A14: Проверка рамок кейса
B15: Лимит бюджета, млн руб. | C15: ='Допущения'!$D$9
B16: Запас до лимита, млн руб. | C16: =C15-C11
B17: Бюджет ≤ лимита? | C17: =IF(C11<=C15,"Да","Нет: превышение")
B18: Срок проекта, мес. | C18: ='Допущения'!$D$70
B19: Лимит срока, мес. | C19: ='Допущения'!$D$10
B20: Срок ≤ лимита? | C20: =IF(C18<=C19,"Да","Нет: превышение")
A22: Эксплуатация после запуска (Opex, с месяца полного эффекта T3)
B23: Команда эксплуатации | C23: ='Допущения'!$D$75*'Допущения'!$D$66*12 | J23: O1 FTE × A22 × 12
B24: Инфраструктура в эксплуатации | C24: ='Допущения'!$D$76
B25: Итого Opex, млн руб./год | C25: =C23+C24

Sheet Эффект
A1: Эффект для банка: годовая основа и денежный поток по месяцам
A2: Иллюстрация механизма, не прогноз. Допущения команды (гипотезы помечены); данные рынка: Банк России, обзор ОБДС, I-II кв. 2026.
B4: Показатель | C4: Ед. | D4: Пессимист | E4: База | F4: Оптимист | G4: Комментарий
B5: Сохраненные средства клиентов (KPI, не доход банка) | C5: млн руб./год | D5: ='KPI'!$E$6 | E5: ='KPI'!$F$6 | F5: ='KPI'!$G$6 | G5: только для KPI
B6: Доля, превращающаяся в избежанный расход банка | C6: % | D6: ='Допущения'!$D$65 | E6: ='Допущения'!$D$65 | F6: ='Допущения'!$D$65 | G6: A21
B7: Избежанный расход банка (возмещения, компенсации, суды) | C7: млн руб./год | D7: =D5*D6 | E7: =E5*E6 | F7: =F5*F6
B8: Экономия на ошибочных ограничениях (прямая) | C8: млн руб./год | D8: ='Ложные срабатывания'!$E$22 | E8: ='Ложные срабатывания'!$F$22 | F8: ='Ложные срабатывания'!$G$22
B9: Удержание клиентов | C9: млн руб./год | D9: ='Ложные срабатывания'!$E$23 | E9: ='Ложные срабатывания'!$F$23 | F9: ='Ложные срабатывания'!$G$23
B10: Итого эффект для банка (валовый) | C10: млн руб./год | D10: =D7+D8+D9 | E10: =E7+E8+E9 | F10: =F7+F8+F9 | G10: 00, разд. 4.5: ≈ 270 в базе
B11: Затраты на эксплуатацию (Opex) | C11: млн руб./год | D11: ='Затраты'!$C$25 | E11: ='Затраты'!$C$25 | F11: ='Затраты'!$C$25
B12: Чистый годовой эффект | C12: млн руб./год | D12: =D10-D11 | E12: =E10-E11 | F12: =F10-F11 | G12: после выхода на полный эффект
B13: Затраты на внедрение (разово) | C13: млн руб. | D13: ='Затраты'!$C$11 | E13: ='Затраты'!$C$11 | F13: ='Затраты'!$C$11
B14: Срок окупаемости от старта проекта | C14: мес. | D14: =IF(COUNTIF($D$32:$AM$32,"<0")>=COLUMNS($D$32:$AM$32),"> 36",COUNTIF($D$32:$AM$32,"<0")+1) | E14: =IF(COUNTIF($D$35:$AM$35,"<0")>=COLUMNS($D$35:$AM$35),"> 36",COUNTIF($D$35:$AM$35,"<0")+1) | F14: =IF(COUNTIF($D$38:$AM$38,"<0")>=COLUMNS($D$38:$AM$38),"> 36",COUNTIF($D$38:$AM$38,"<0")+1) | G14: первый месяц с накопленным ≥ 0
B15: Накопленный чистый эффект за 12 мес. | C15: млн руб. | D15: =INDEX($D$32:$AM$32,1,12) | E15: =INDEX($D$35:$AM$35,1,12) | F15: =INDEX($D$38:$AM$38,1,12)
B16: Накопленный чистый эффект за 24 мес. | C16: млн руб. | D16: =INDEX($D$32:$AM$32,1,24) | E16: =INDEX($D$35:$AM$35,1,24) | F16: =INDEX($D$38:$AM$38,1,24)
B17: Накопленный чистый эффект за 36 мес. | C17: млн руб. | D17: =INDEX($D$32:$AM$32,1,36) | E17: =INDEX($D$35:$AM$35,1,36) | F17: =INDEX($D$38:$AM$38,1,36)
B18: NPV за 36 мес. | C18: млн руб. | D18: =NPV((1+'Допущения'!$D$67)^(1/12)-1,$D$31:$AM$31) | E18: =NPV((1+'Допущения'!$D$67)^(1/12)-1,$D$34:$AM$34) | F18: =NPV((1+'Допущения'!$D$67)^(1/12)-1,$D$37:$AM$37) | G18: ставка A23, помесячно
A24: Денежный поток по месяцам от старта проекта (М1-М6 внедрение, М5-М6 пилот, с М7 полный эффект)
B25: Показатель | C25: Ед. | D25: М1 | E25: М2 | F25: М3 | G25: М4 | H25: М5 | I25: М6 | J25: М7 | K25: М8 | L25: М9 | M25: М10 | N25: М11 | O25: М12 | P25: М13 | Q25: М14 | R25: М15 | S25: М16 | T25: М17 | U25: М18 | V25: М19 | W25: М20 | X25: М21 | Y25: М22 | Z25: М23 | AA25: М24 | AB25: М25 | AC25: М26 | AD25: М27 | AE25: М28 | AF25: М29 | AG25: М30 | AH25: М31 | AI25: М32 | AJ25: М33 | AK25: М34 | AL25: М35 | AM25: М36
B26: Номер месяца | D26: 1 | E26: 2 | F26: 3 | G26: 4 | H26: 5 | I26: 6 | J26: 7 | K26: 8 | L26: 9 | M26: 10 | N26: 11 | O26: 12 | P26: 13 | Q26: 14 | R26: 15 | S26: 16 | T26: 17 | U26: 18 | V26: 19 | W26: 20 | X26: 21 | Y26: 22 | Z26: 23 | AA26: 24 | AB26: 25 | AC26: 26 | AD26: 27 | AE26: 28 | AF26: 29 | AG26: 30 | AH26: 31 | AI26: 32 | AJ26: 33 | AK26: 34 | AL26: 35 | AM26: 36
B27: Доля эффекта (пилот / полный) | C27: % | D27: =IF(D$26>='Допущения'!$D$79,1,IF(D$26>='Допущения'!$D$77,'Допущения'!$D$78,0)) | E27: =IF(E$26>='Допущения'!$D$79,1,IF(E$26>='Допущения'!$D$77,'Допущения'!$D$78,0)) | F27: =IF(F$26>='Допущения'!$D$79,1,IF(F$26>='Допущения'!$D$77,'Допущения'!$D$78,0)) | G27: =IF(G$26>='Допущения'!$D$79,1,IF(G$26>='Допущения'!$D$77,'Допущения'!$D$78,0)) | H27: =IF(H$26>='Допущения'!$D$79,1,IF(H$26>='Допущения'!$D$77,'Допущения'!$D$78,0)) | I27: =IF(I$26>='Допущения'!$D$79,1,IF(I$26>='Допущения'!$D$77,'Допущения'!$D$78,0)) | J27: =IF(J$26>='Допущения'!$D$79,1,IF(J$26>='Допущения'!$D$77,'Допущения'!$D$78,0)) | K27: =IF(K$26>='Допущения'!$D$79,1,IF(K$26>='Допущения'!$D$77,'Допущения'!$D$78,0)) | ... AM27: =IF(AM$26>='Допущения'!$D$79,1,IF(AM$26>='Допущения'!$D$77,'Допущения'!$D$78,0))
B28: Затраты на внедрение | C28: млн руб. | D28: =IF(D$26<=COLUMNS('Затраты'!$D$11:$I$11),INDEX('Затраты'!$D$11:$I$11,1,D$26),0) | E28: =IF(E$26<=COLUMNS('Затраты'!$D$11:$I$11),INDEX('Затраты'!$D$11:$I$11,1,E$26),0) | F28: =IF(F$26<=COLUMNS('Затраты'!$D$11:$I$11),INDEX('Затраты'!$D$11:$I$11,1,F$26),0) | G28: =IF(G$26<=COLUMNS('Затраты'!$D$11:$I$11),INDEX('Затраты'!$D$11:$I$11,1,G$26),0) | H28: =IF(H$26<=COLUMNS('Затраты'!$D$11:$I$11),INDEX('Затраты'!$D$11:$I$11,1,H$26),0) | I28: =IF(I$26<=COLUMNS('Затраты'!$D$11:$I$11),INDEX('Затраты'!$D$11:$I$11,1,I$26),0) | J28: =IF(J$26<=COLUMNS('Затраты'!$D$11:$I$11),INDEX('Затраты'!$D$11:$I$11,1,J$26),0) | K28: =IF(K$26<=COLUMNS('Затраты'!$D$11:$I$11),INDEX('Затраты'!$D$11:$I$11,1,K$26),0) | ... AM28: =IF(AM$26<=COLUMNS('Затраты'!$D$11:$I$11),INDEX('Затраты'!$D$11:$I$11,1,AM$26),0)
B29: Затраты на эксплуатацию | C29: млн руб. | D29: =IF(D$26>='Допущения'!$D$79,'Затраты'!$C$25/12,0) | E29: =IF(E$26>='Допущения'!$D$79,'Затраты'!$C$25/12,0) | F29: =IF(F$26>='Допущения'!$D$79,'Затраты'!$C$25/12,0) | G29: =IF(G$26>='Допущения'!$D$79,'Затраты'!$C$25/12,0) | H29: =IF(H$26>='Допущения'!$D$79,'Затраты'!$C$25/12,0) | I29: =IF(I$26>='Допущения'!$D$79,'Затраты'!$C$25/12,0) | J29: =IF(J$26>='Допущения'!$D$79,'Затраты'!$C$25/12,0) | K29: =IF(K$26>='Допущения'!$D$79,'Затраты'!$C$25/12,0) | ... AM29: =IF(AM$26>='Допущения'!$D$79,'Затраты'!$C$25/12,0)
B30: Пессимист: валовый эффект | C30: млн руб. | D30: =$D$10/12*D$27 | E30: =$D$10/12*E$27 | F30: =$D$10/12*F$27 | G30: =$D$10/12*G$27 | H30: =$D$10/12*H$27 | I30: =$D$10/12*I$27 | J30: =$D$10/12*J$27 | K30: =$D$10/12*K$27 | ... AM30: =$D$10/12*AM$27
B31: Пессимист: чистый поток | C31: млн руб. | D31: =D30-D$28-D$29 | E31: =E30-E$28-E$29 | F31: =F30-F$28-F$29 | G31: =G30-G$28-G$29 | H31: =H30-H$28-H$29 | I31: =I30-I$28-I$29 | J31: =J30-J$28-J$29 | K31: =K30-K$28-K$29 | ... AM31: =AM30-AM$28-AM$29
B32: Пессимист: накопленный итог | C32: млн руб. | D32: =D31 | E32: =D32+E31 | F32: =E32+F31 | G32: =F32+G31 | H32: =G32+H31 | I32: =H32+I31 | J32: =I32+J31 | K32: =J32+K31 | L32: =K32+L31 | ... AM32: =AL32+AM31
B33: База: валовый эффект | C33: млн руб. | D33: =$E$10/12*D$27 | E33: =$E$10/12*E$27 | F33: =$E$10/12*F$27 | G33: =$E$10/12*G$27 | H33: =$E$10/12*H$27 | I33: =$E$10/12*I$27 | J33: =$E$10/12*J$27 | K33: =$E$10/12*K$27 | ... AM33: =$E$10/12*AM$27
B34: База: чистый поток | C34: млн руб. | D34: =D33-D$28-D$29 | E34: =E33-E$28-E$29 | F34: =F33-F$28-F$29 | G34: =G33-G$28-G$29 | H34: =H33-H$28-H$29 | I34: =I33-I$28-I$29 | J34: =J33-J$28-J$29 | K34: =K33-K$28-K$29 | ... AM34: =AM33-AM$28-AM$29
B35: База: накопленный итог | C35: млн руб. | D35: =D34 | E35: =D35+E34 | F35: =E35+F34 | G35: =F35+G34 | H35: =G35+H34 | I35: =H35+I34 | J35: =I35+J34 | K35: =J35+K34 | L35: =K35+L34 | ... AM35: =AL35+AM34
B36: Оптимист: валовый эффект | C36: млн руб. | D36: =$F$10/12*D$27 | E36: =$F$10/12*E$27 | F36: =$F$10/12*F$27 | G36: =$F$10/12*G$27 | H36: =$F$10/12*H$27 | I36: =$F$10/12*I$27 | J36: =$F$10/12*J$27 | K36: =$F$10/12*K$27 | ... AM36: =$F$10/12*AM$27
B37: Оптимист: чистый поток | C37: млн руб. | D37: =D36-D$28-D$29 | E37: =E36-E$28-E$29 | F37: =F36-F$28-F$29 | G37: =G36-G$28-G$29 | H37: =H36-H$28-H$29 | I37: =I36-I$28-I$29 | J37: =J36-J$28-J$29 | K37: =K36-K$28-K$29 | ... AM37: =AM36-AM$28-AM$29
B38: Оптимист: накопленный итог | C38: млн руб. | D38: =D37 | E38: =D38+E37 | F38: =E38+F37 | G38: =F38+G37 | H38: =G38+H37 | I38: =H38+I37 | J38: =I38+J37 | K38: =J38+K37 | L38: =K38+L37 | ... AM38: =AL38+AM37

Sheet Сценарии
A1: Сценарии: пессимистичный / базовый / оптимистичный
A2: Иллюстрация механизма, не прогноз. Допущения команды (гипотезы помечены); данные рынка: Банк России, обзор ОБДС, I-II кв. 2026.
B4: Показатель | C4: Ед. | D4: Пессимист | E4: База | F4: Оптимист
A5: Что меняется между сценариями (входы на листе «Допущения»)
B6: Полнота выявления после (A8) | C6: % | D6: ='Допущения'!$C$37 | E6: ='Допущения'!$D$37 | F6: ='Допущения'!$E$37
B7: Сокращение потерь (A9) | C7: % | D7: ='Допущения'!$C$38 | E7: ='Допущения'!$D$38 | F7: ='Допущения'!$E$38
B8: Доля сигналов → ошибочное ограничение после (A12) | C8: % | D8: ='Допущения'!$C$47 | E8: ='Допущения'!$D$47 | F8: ='Допущения'!$E$47
B9: Снижение числа попыток (A9a) | C9: % | D9: ='Допущения'!$C$39 | E9: ='Допущения'!$D$39 | F9: ='Допущения'!$E$39
A10: KPI
B11: Потери клиентов ВТБ в фокусе: было | C11: млн руб./год | D11: ='Допущения'!$D$34 | E11: ='Допущения'!$D$34 | F11: ='Допущения'!$D$34
B12: Потери клиентов ВТБ в фокусе: стало | C12: млн руб./год | D12: ='KPI'!$E$5 | E12: ='KPI'!$F$5 | F12: ='KPI'!$G$5
B13: Сохраненные средства клиентов (KPI, не доход банка) | C13: млн руб./год | D13: ='KPI'!$E$6 | E13: ='KPI'!$F$6 | F13: ='KPI'!$G$6
B14: Ошибочные ограничения: было | C14: % законных | D14: ='Допущения'!$D$48 | E14: ='Допущения'!$D$48 | F14: ='Допущения'!$D$48
B15: Ошибочные ограничения: стало | C15: % законных | D15: ='KPI'!$E$11 | E15: ='KPI'!$F$11 | F15: ='KPI'!$G$11
B16: Изменение NPS банка | C16: п. | D16: ='NPS'!$E$10 | E16: ='NPS'!$F$10 | F16: ='NPS'!$G$10
A17: Экономика банка
B18: Избежанный расход банка | C18: млн руб./год | D18: ='Эффект'!$D$7 | E18: ='Эффект'!$E$7 | F18: ='Эффект'!$F$7
B19: Экономия на ошибочных ограничениях | C19: млн руб./год | D19: ='Эффект'!$D$8 | E19: ='Эффект'!$E$8 | F19: ='Эффект'!$F$8
B20: Удержание клиентов | C20: млн руб./год | D20: ='Эффект'!$D$9 | E20: ='Эффект'!$E$9 | F20: ='Эффект'!$F$9
B21: Итого эффект для банка (валовый) | C21: млн руб./год | D21: ='Эффект'!$D$10 | E21: ='Эффект'!$E$10 | F21: ='Эффект'!$F$10
B22: Затраты на эксплуатацию | C22: млн руб./год | D22: ='Эффект'!$D$11 | E22: ='Эффект'!$E$11 | F22: ='Эффект'!$F$11
B23: Чистый годовой эффект | C23: млн руб./год | D23: ='Эффект'!$D$12 | E23: ='Эффект'!$E$12 | F23: ='Эффект'!$F$12
B24: Затраты на внедрение | C24: млн руб. | D24: ='Эффект'!$D$13 | E24: ='Эффект'!$E$13 | F24: ='Эффект'!$F$13
B25: Срок окупаемости от старта проекта | C25: мес. | D25: ='Эффект'!$D$14 | E25: ='Эффект'!$E$14 | F25: ='Эффект'!$F$14
B26: Накопленный чистый эффект за 36 мес. | C26: млн руб. | D26: ='Эффект'!$D$17 | E26: ='Эффект'!$E$17 | F26: ='Эффект'!$F$17
B27: NPV за 36 мес. | C27: млн руб. | D27: ='Эффект'!$D$18 | E27: ='Эффект'!$E$18 | F27: ='Эффект'!$F$18
B28: Бюджет ≤ 50 млн? | D28: ='Затраты'!$C$17 | E28: ='Затраты'!$C$17 | F28: ='Затраты'!$C$17
B29: Срок ≤ 6 мес.? | D29: ='Затраты'!$C$20 | E29: ='Затраты'!$C$20 | F29: ='Затраты'!$C$20

Sheet Чувствительность
A1: Чувствительность чистого годового эффекта (базовый сценарий) к ключевым допущениям
A2: Иллюстрация механизма, не прогноз. Допущения команды (гипотезы помечены); данные рынка: Банк России, обзор ОБДС, I-II кв. 2026.
B4: Шаг изменения допущения (S1) | C4: ='Допущения'!$D$88
B5: Чистый годовой эффект, база (замкнутая формула), млн руб. | C5: ='Допущения'!$D$34*'KPI'!$F$7*'Допущения'!$D$65+'Допущения'!$D$43*('Допущения'!$D$48-'Допущения'!$D$49)*('Допущения'!$D$59+'Допущения'!$D$61*'Допущения'!$D$62/'Допущения'!$D$60)-'Затраты'!$C$25
B6: Сверка с листом «Эффект» | C6: =IF(ABS(C5-'Эффект'!$E$12)<0.001,"OK","Расхождение")
B8: Допущение | C8: Базовое значение | D8: Эффект при −S1 | E8: Эффект при +S1 | F8: Изменение при −S1 | G8: Изменение при +S1 | H8: Размах
B9: Доля ВТБ в потерях фокуса (A5) | C9: ='Допущения'!$D$33 | D9: ='Допущения'!$D$34*(1-'Допущения'!$D$88)*'KPI'!$F$7*'Допущения'!$D$65+'Допущения'!$D$43*('Допущения'!$D$48-'Допущения'!$D$49)*('Допущения'!$D$59+'Допущения'!$D$61*'Допущения'!$D$62/'Допущения'!$D$60)-'Затраты'!$C$25 | E9: ='Допущения'!$D$34*(1+'Допущения'!$D$88)*'KPI'!$F$7*'Допущения'!$D$65+'Допущения'!$D$43*('Допущения'!$D$48-'Допущения'!$D$49)*('Допущения'!$D$59+'Допущения'!$D$61*'Допущения'!$D$62/'Допущения'!$D$60)-'Затраты'!$C$25 | F9: =D9-$C$5 | G9: =E9-$C$5 | H9: =ABS(G9-F9)
B10: Сокращение потерь (A9, база) | C10: ='KPI'!$F$7 | D10: ='Допущения'!$D$34*'KPI'!$F$7*(1-'Допущения'!$D$88)*'Допущения'!$D$65+'Допущения'!$D$43*('Допущения'!$D$48-'Допущения'!$D$49)*('Допущения'!$D$59+'Допущения'!$D$61*'Допущения'!$D$62/'Допущения'!$D$60)-'Затраты'!$C$25 | E10: ='Допущения'!$D$34*'KPI'!$F$7*(1+'Допущения'!$D$88)*'Допущения'!$D$65+'Допущения'!$D$43*('Допущения'!$D$48-'Допущения'!$D$49)*('Допущения'!$D$59+'Допущения'!$D$61*'Допущения'!$D$62/'Допущения'!$D$60)-'Затраты'!$C$25 | F10: =D10-$C$5 | G10: =E10-$C$5 | H10: =ABS(G10-F10)
B11: Доля сохраненных средств → избежанный расход банка (A21) | C11: ='Допущения'!$D$65 | D11: ='Допущения'!$D$34*'KPI'!$F$7*'Допущения'!$D$65*(1-'Допущения'!$D$88)+'Допущения'!$D$43*('Допущения'!$D$48-'Допущения'!$D$49)*('Допущения'!$D$59+'Допущения'!$D$61*'Допущения'!$D$62/'Допущения'!$D$60)-'Затраты'!$C$25 | E11: ='Допущения'!$D$34*'KPI'!$F$7*'Допущения'!$D$65*(1+'Допущения'!$D$88)+'Допущения'!$D$43*('Допущения'!$D$48-'Допущения'!$D$49)*('Допущения'!$D$59+'Допущения'!$D$61*'Допущения'!$D$62/'Допущения'!$D$60)-'Затраты'!$C$25 | F11: =D11-$C$5 | G11: =E11-$C$5 | H11: =ABS(G11-F11)
B12: Стоимость одного ошибочного ограничения (A16), руб. | C12: ='Допущения'!$D$59 | D12: ='Допущения'!$D$34*'KPI'!$F$7*'Допущения'!$D$65+'Допущения'!$D$43*('Допущения'!$D$48-'Допущения'!$D$49)*('Допущения'!$D$59*(1-'Допущения'!$D$88)+'Допущения'!$D$61*'Допущения'!$D$62/'Допущения'!$D$60)-'Затраты'!$C$25 | E12: ='Допущения'!$D$34*'KPI'!$F$7*'Допущения'!$D$65+'Допущения'!$D$43*('Допущения'!$D$48-'Допущения'!$D$49)*('Допущения'!$D$59*(1+'Допущения'!$D$88)+'Допущения'!$D$61*'Допущения'!$D$62/'Допущения'!$D$60)-'Затраты'!$C$25 | F12: =D12-$C$5 | G12: =E12-$C$5 | H12: =ABS(G12-F12)
B13: Объем законных переводов в фокусе (A10), млн/год | C13: ='Допущения'!$D$43 | D13: ='Допущения'!$D$34*'KPI'!$F$7*'Допущения'!$D$65+'Допущения'!$D$43*(1-'Допущения'!$D$88)*('Допущения'!$D$48-'Допущения'!$D$49)*('Допущения'!$D$59+'Допущения'!$D$61*'Допущения'!$D$62/'Допущения'!$D$60)-'Затраты'!$C$25 | E13: ='Допущения'!$D$34*'KPI'!$F$7*'Допущения'!$D$65+'Допущения'!$D$43*(1+'Допущения'!$D$88)*('Допущения'!$D$48-'Допущения'!$D$49)*('Допущения'!$D$59+'Допущения'!$D$61*'Допущения'!$D$62/'Допущения'!$D$60)-'Затраты'!$C$25 | F13: =D13-$C$5 | G13: =E13-$C$5 | H13: =ABS(G13-F13)
B14: Ошибочные ограничения после (A13 = A11 × A12) | C14: ='Допущения'!$D$49 | D14: ='Допущения'!$D$34*'KPI'!$F$7*'Допущения'!$D$65+'Допущения'!$D$43*('Допущения'!$D$48-'Допущения'!$D$49*(1-'Допущения'!$D$88))*('Допущения'!$D$59+'Допущения'!$D$61*'Допущения'!$D$62/'Допущения'!$D$60)-'Затраты'!$C$25 | E14: ='Допущения'!$D$34*'KPI'!$F$7*'Допущения'!$D$65+'Допущения'!$D$43*('Допущения'!$D$48-'Допущения'!$D$49*(1+'Допущения'!$D$88))*('Допущения'!$D$59+'Допущения'!$D$61*'Допущения'!$D$62/'Допущения'!$D$60)-'Затраты'!$C$25 | F14: =D14-$C$5 | G14: =E14-$C$5 | H14: =ABS(G14-F14)
B15: Дополнительный отток после ограничения (A18) | C15: ='Допущения'!$D$61 | D15: ='Допущения'!$D$34*'KPI'!$F$7*'Допущения'!$D$65+'Допущения'!$D$43*('Допущения'!$D$48-'Допущения'!$D$49)*('Допущения'!$D$59+'Допущения'!$D$61*(1-'Допущения'!$D$88)*'Допущения'!$D$62/'Допущения'!$D$60)-'Затраты'!$C$25 | E15: ='Допущения'!$D$34*'KPI'!$F$7*'Допущения'!$D$65+'Допущения'!$D$43*('Допущения'!$D$48-'Допущения'!$D$49)*('Допущения'!$D$59+'Допущения'!$D$61*(1+'Допущения'!$D$88)*'Допущения'!$D$62/'Допущения'!$D$60)-'Затраты'!$C$25 | F15: =D15-$C$5 | G15: =E15-$C$5 | H15: =ABS(G15-F15)
B16: Годовой доход на клиента (A19), руб. | C16: ='Допущения'!$D$62 | D16: ='Допущения'!$D$34*'KPI'!$F$7*'Допущения'!$D$65+'Допущения'!$D$43*('Допущения'!$D$48-'Допущения'!$D$49)*('Допущения'!$D$59+'Допущения'!$D$61*'Допущения'!$D$62*(1-'Допущения'!$D$88)/'Допущения'!$D$60)-'Затраты'!$C$25 | E16: ='Допущения'!$D$34*'KPI'!$F$7*'Допущения'!$D$65+'Допущения'!$D$43*('Допущения'!$D$48-'Допущения'!$D$49)*('Допущения'!$D$59+'Допущения'!$D$61*'Допущения'!$D$62*(1+'Допущения'!$D$88)/'Допущения'!$D$60)-'Затраты'!$C$25 | F16: =D16-$C$5 | G16: =E16-$C$5 | H16: =ABS(G16-F16)
B17: Затраты на эксплуатацию (Opex), млн руб./год | C17: ='Затраты'!$C$25 | D17: ='Допущения'!$D$34*'KPI'!$F$7*'Допущения'!$D$65+'Допущения'!$D$43*('Допущения'!$D$48-'Допущения'!$D$49)*('Допущения'!$D$59+'Допущения'!$D$61*'Допущения'!$D$62/'Допущения'!$D$60)-'Затраты'!$C$25*(1-'Допущения'!$D$88) | E17: ='Допущения'!$D$34*'KPI'!$F$7*'Допущения'!$D$65+'Допущения'!$D$43*('Допущения'!$D$48-'Допущения'!$D$49)*('Допущения'!$D$59+'Допущения'!$D$61*'Допущения'!$D$62/'Допущения'!$D$60)-'Затраты'!$C$25*(1+'Допущения'!$D$88) | F17: =D17-$C$5 | G17: =E17-$C$5 | H17: =ABS(G17-F17)
B19: Эффект = A6 × сокращение потерь × A21 + A10 × (A13 сейчас − A13 после) × (A16 + A18 × A19 / A17) − Opex

Sheet Варианты
A1: Варианты В1-В4: взвешенная оценка, стоимость, срок, симуляция (слайд 3)
A2: Иллюстрация механизма, не прогноз. Допущения команды (гипотезы помечены); данные рынка: Банк России, обзор ОБДС, I-II кв. 2026.
B4: Фактор | C4: Вес | D4: В1 | E4: В2 | F4: В3 | G4: В4
B5: ='Допущения'!$B$99 | C5: ='Допущения'!$C$99 | D5: ='Допущения'!$D$99 | E5: ='Допущения'!$E$99 | F5: ='Допущения'!$F$99 | G5: ='Допущения'!$G$99
B6: ='Допущения'!$B$100 | C6: ='Допущения'!$C$100 | D6: ='Допущения'!$D$100 | E6: ='Допущения'!$E$100 | F6: ='Допущения'!$F$100 | G6: ='Допущения'!$G$100
B7: ='Допущения'!$B$101 | C7: ='Допущения'!$C$101 | D7: ='Допущения'!$D$101 | E7: ='Допущения'!$E$101 | F7: ='Допущения'!$F$101 | G7: ='Допущения'!$G$101
B8: ='Допущения'!$B$102 | C8: ='Допущения'!$C$102 | D8: ='Допущения'!$D$102 | E8: ='Допущения'!$E$102 | F8: ='Допущения'!$F$102 | G8: ='Допущения'!$G$102
B9: ='Допущения'!$B$103 | C9: ='Допущения'!$C$103 | D9: ='Допущения'!$D$103 | E9: ='Допущения'!$E$103 | F9: ='Допущения'!$F$103 | G9: ='Допущения'!$G$103
B10: ='Допущения'!$B$104 | C10: ='Допущения'!$C$104 | D10: ='Допущения'!$D$104 | E10: ='Допущения'!$E$104 | F10: ='Допущения'!$F$104 | G10: ='Допущения'!$G$104
B11: ='Допущения'!$B$105 | C11: ='Допущения'!$C$105 | D11: ='Допущения'!$D$105 | E11: ='Допущения'!$E$105 | F11: ='Допущения'!$F$105 | G11: ='Допущения'!$G$105
B12: ='Допущения'!$B$106 | C12: ='Допущения'!$C$106 | D12: ='Допущения'!$D$106 | E12: ='Допущения'!$E$106 | F12: ='Допущения'!$F$106 | G12: ='Допущения'!$G$106
B13: Итого (взвешенная оценка) | D13: =SUMPRODUCT($C$5:$C$12,D5:D12) | E13: =SUMPRODUCT($C$5:$C$12,E5:E12) | F13: =SUMPRODUCT($C$5:$C$12,F5:F12) | G13: =SUMPRODUCT($C$5:$C$12,G5:G12)
B14: Место | D14: =RANK(D13,$D$13:$G$13) | E14: =RANK(E13,$D$13:$G$13) | F14: =RANK(F13,$D$13:$G$13) | G14: =RANK(G13,$D$13:$G$13)
B16: Параметр | D16: В1 | E16: В2 | F16: В3 | G16: В4
B17: Стоимость внедрения (оценка), млн руб. | D17: ='Допущения'!$D$81 | E17: ='Допущения'!$D$83 | F17: ='Затраты'!$C$11 | G17: ='Допущения'!$D$85
B18: Срок внедрения (оценка), мес. | D18: ='Допущения'!$D$82 | E18: ='Допущения'!$D$84 | F18: ='Допущения'!$D$70 | G18: ='Допущения'!$D$86
B19: В рамках кейса (≤ 50 млн, ≤ 6 мес.)? | D19: =IF(AND(D17<='Допущения'!$D$9,D18<='Допущения'!$D$10),"Да","Нет") | E19: =IF(AND(E17<='Допущения'!$D$9,E18<='Допущения'!$D$10),"Да","Нет") | F19: =IF(AND(F17<='Допущения'!$D$9,F18<='Допущения'!$D$10),"Да","Нет") | G19: =IF(AND(G17<='Допущения'!$D$9,G18<='Допущения'!$D$10),"Да","Нет")
A21: Симуляция на синтетических данных: иллюстрация механизма, не прогноз (значения из out/sim_variants_metrics.csv)
B22: Метрика | C22: Ед. | D22: В1 | E22: В2 | F22: В3 | G22: В4
B23: TP: мошеннические операции с сигналом | C23: шт. | D23: 532 | E23: 564 | F23: 629 | G23: 488
B24: FP: законные операции с сигналом | C24: шт. | D24: 4996 | E24: 1139 | F24: 3092 | G24: 1200
B25: FN: мошеннические операции без сигнала | C25: шт. | D25: 161 | E25: 129 | F25: 64 | G25: 205
B26: TN: законные операции без сигнала | C26: шт. | D26: 223629 | E26: 227486 | F26: 225533 | G26: 227425
B27: Точность = TP / (TP + FP) | C27: % | D27: 0.096237337 | E27: 0.33118027 | F27: 0.16904058 | G27: 0.28909953
B28: Полнота = TP / (TP + FN) | C28: % | D28: 0.76767677 | E28: 0.81385281 | F28: 0.90764791 | G28: 0.7041847
B29: Доля ложных срабатываний среди законных = FP / (FP + TN) | C29: % | D29: 0.021852378 | E29: 0.0049819574 | F29: 0.01352433 | G29: 0.0052487698
B30: Ошибочные ограничения (законные операции остановлены) | C30: шт. | D30: 1213.2 | E30: 1139 | F30: 1094.76 | G30: 1200
B31: Ошибочные ограничения, доля законных | C31: % | D31: 0.0053065063 | E31: 0.0049819574 | F31: 0.0047884527 | G31: 0.0052487698
B32: Доля сигналов, снятых без ограничения | C32: % | D32: 0.75716573 | E32: 0 | F32: 0.6459379 | G32: 0
B33: Предотвращенные потери, % от суммы попыток | C33: % | D33: 0.53668778 | E33: 0.61044804 | F33: 0.7289127 | G33: 0.62381636
B34: Непредотвращенные потери, % от суммы попыток | C34: % | D34: 0.46331222 | E34: 0.38955196 | F34: 0.2710873 | G34: 0.37618364
B35: Ошибочные ограничения при равных потерях (35% суммы попыток) | C35: % | D35: 0.012962187 | E35: 0.0081968289 | F35: 0.0037263641 | G35: 0.0057255331
B36: Синтетические данные; сигнал = любая мера кроме «пропустить», ограничение = пауза, звонок, отказ.
B37: Рабочие точки: В1 базовые пороги; В2-В4 минимум потерь при ограничениях не выше, чем у В1 (равное трение).
